Workbook

Sheet Todo
A1: TONELADAS POR HECTARIA
B2: Córdoba | D2: Guajira 2 | F2: Guajira 3 | H2: Guajira 4 | J2: Guajira | L2: Antioquia 5 | N2: Antioquia 6 | P2: Antioquia | R2: Atlantico 7 | T2: Atlantico 8 | V2: Atlántico | X2: Magdalena 9 | Z2: Magdalena 10 | AB2: Magdalena | AD2: Cesar 11 | AF2: Cesar 12 | AH2: Cesar | AJ2: Bolivar 13 | AL2: Bolivar 14 | AN2: Bolívar | AP2: Chocó
B3: Sin Irrigación | C3: Con Irrigación | D3: Sin Irrigación | E3: Con Irrigación | F3: Sin Irrigación | G3: Con Irrigación | H3: Sin Irrigación | I3: Con Irrigación | J3: Sin Irrigación | K3: Con Irrigación | L3: Sin Irrigación | M3: Con Irrigación | N3: Sin Irrigación | O3: Con Irrigación | P3: Sin Irrigación | Q3: Con Irrigación | R3: Sin Irrigación | S3: Con Irrigación | T3: Sin Irrigación | U3: Con Irrigación | V3: Sin Irrigación | W3: Con Irrigación | X3: Sin Irrigación | Y3: Con Irrigación | Z3: Sin Irrigación | AA3: Con Irrigación | AB3: Sin Irrigación | AC3: Con Irrigación | AD3: Sin Irrigación | AE3: Con Irrigación | AF3: Sin Irrigación | AG3: Con Irrigación | AH3: Sin Irrigación | AI3: Con Irrigación | AJ3: Sin Irrigación | AK3: Con Irrigación | AL3: Sin Irrigación | AM3: Con Irrigación | AN3: Sin Irrigación | AO3: Con Irrigación | AP3: Sin Irrigación | AQ3: Con Irrigación
A4: 2000 | B4: {=Resumen_Cordoba1!$O$23:$O$43} -> 0.016618811 | C4: {=Resumen_Cordoba1!$O$2:$O$22} -> 59.697321 | D4: {=Resumen_Guajira2!$O$23:$O$43} -> 0 | E4: {=Resumen_Guajira2!$O$2:$O$22} -> 62.575948 | F4: {=Resumen_Guajira3!$O$23:$O$43} -> 0 | G4: {=Resumen_Guajira3!$O$2:$O$22} -> 72.248168 | H4: {=Resumen_Guajira4!$O$23:$O$43} -> 0.00024250421 | I4: {=Resumen_Guajira4!$O$2:$O$22} -> 65.545233 | J4: =AVERAGE(D4,F4,H4) -> 8.0834738e-05 | K4: =AVERAGE(E4,G4,I4) -> 66.789783 | L4: {=Resumen_Antioquia5!$O$22:$O$41} -> 0.019967441 | M4: {=Resumen_Antioquia5!$O$2:$O$21} -> 90.930683 | N4: {=Resumen_Antioquia6!$O$23:$O$43} -> 4.6806242e-05 | O4: {=Resumen_Antioquia6!$O$2:$O$22} -> 111.1378 | P4: =AVERAGE(L4,N4) -> 0.010007124 | Q4: =AVERAGE(M4,O4) -> 101.03424 | R4: {=Resumen_Atlantico7!$O$23:$O$43} -> 0.043715909 | S4: {=Resumen_Atlantico7!$O$2:$O$22} -> 67.590892 | T4: {=Resumen_Atlantico8!$O$23:$O$43} -> 0.00064167877 | U4: {=Resumen_Atlantico8!$O$2:$O$22} -> 45.061638 | V4: =AVERAGE(R4,T4) -> 0.022178794 | W4: =AVERAGE(S4,U4) -> 56.326265 | X4: {=Resumen_Magdalena9!$O$23:$O$43} -> 0.0098972171 | Y4: {=Resumen_Magdalena9!$O$2:$O$22} -> 57.061847 | Z4: {=Resumen_Magdalena10!$O$23:$O$43} -> 0.011626531 | AA4: {=Resumen_Magdalena10!$O$2:$O$22} -> 67.291991 | AB4: =AVERAGE(X4,Z4) -> 0.010761874 | AC4: =AVERAGE(Y4,AA4) -> 62.176919 | AD4: {=Resumen_Cesar11!$O$23:$O$43} -> 0.020563016 | AE4: {=Resumen_Cesar11!$O$2:$O$22} -> 54.666705 | AF4: {=Resumen_Cesar12!$O$23:$O$43} -> 0.024534332 | AG4: {=Resumen_Cesar12!$O$2:$O$22} -> 44.874769 | AH4: =AVERAGE(AD4,AF4) -> 0.022548674 | AI4: =AVERAGE(AE4,AG4) -> 49.770737 | AJ4: {=Resumen_Bolivar13!$O$23:$O$43} -> 0.079968898 | AK4: {=Resumen_Bolivar13!$O$2:$O$22} -> 66.228043 | AL4: {=Resumen_Bolivar14!$O$23:$O$43} -> 0.12111156 | AM4: {=Resumen_Bolivar14!$O$2:$O$22} -> 65.363617 | AN4: =AVERAGE(AJ4,AL4) -> 0.10054023 | AO4: =AVERAGE(AK4,AM4) -> 65.79583 | AP4: {=Resumen_Choco15!$O$23:$O$43} -> 1.2498461 | AQ4: {=Resumen_Choco15!$O$2:$O$22} -> 71.228973
A5: 2001 | B5: 0.015267563 | C5: 56.257969 | D5: 0 | E5: 62.271139 | F5: 0 | G5: 69.42748 | H5: 0.00019028387 | I5: 66.724671 | J5: =AVERAGE(D5,F5,H5) -> 6.3427957e-05 | K5: =AVERAGE(E5,G5,I5) -> 66.141097 | L5: 0.017799403 | M5: 86.507744 | N5: 6.1356256e-05 | O5: 114.94314 | P5: =AVERAGE(L5,N5) -> 0.0089303797 | Q5: =AVERAGE(M5,O5) -> 100.72544 | R5: 71.296554 | S5: 71.296554 | T5: 0.00069216862 | U5: 48.882001 | V5: =AVERAGE(R5,T5) -> 35.648623 | W5: =AVERAGE(S5,U5) -> 60.089277 | X5: 0.010231377 | Y5: 57.347107 | Z5: 0.01256193 | AA5: 67.659072 | AB5: =AVERAGE(X5,Z5) -> 0.011396653 | AC5: =AVERAGE(Y5,AA5) -> 62.503089 | AD5: 0.020761013 | AE5: 49.542132 | AF5: 0.02381974 | AG5: 40.127564 | AH5: =AVERAGE(AD5,AF5) -> 0.022290376 | AI5: =AVERAGE(AE5,AG5) -> 44.834848 | AJ5: 0.039890433 | AK5: 56.964824 | AL5: 0.060215336 | AM5: 59.150724 | AN5: =AVERAGE(AJ5,AL5) -> 0.050052884 | AO5: =AVERAGE(AK5,AM5) -> 58.057774 | AP5: 0.88811914 | AQ5: 70.098526
A6: 2002 | B6: 0.012132994 | C6: 43.098503 | D6: 0 | E6: 60.301063 | F6: 0 | G6: 61.532176 | H6: 0.00020688743 | I6: 82.94456 | J6: =AVERAGE(D6,F6,H6) -> 6.8962478e-05 | K6: =AVERAGE(E6,G6,I6) -> 68.259266 | L6: 0.015521245 | M6: 84.757823 | N6: 6.8437668e-05 | O6: 111.4307 | P6: =AVERAGE(L6,N6) -> 0.0077948415 | Q6: =AVERAGE(M6,O6) -> 98.094262 | R6: 0.065558593 | S6: 70.201317 | T6: 0.00068882504 | U6: 48.054246 | V6: =AVERAGE(R6,T6) -> 0.033123709 | W6: =AVERAGE(S6,U6) -> 59.127781 | X6: 0.0067595762 | Y6: 47.478759 | Z6: 0.012557599 | AA6: 67.454846 | AB6: =AVERAGE(X6,Z6) -> 0.0096585878 | AC6: =AVERAGE(Y6,AA6) -> 57.466802 | AD6: 0.016690475 | AE6: 40.10207 | AF6: 0.023784979 | AG6: 39.383464 | AH6: =AVERAGE(AD6,AF6) -> 0.020237727 | AI6: =AVERAGE(AE6,AG6) -> 39.742767 | AJ6: 0.085302233 | AK6: 55.807893 | AL6: 0.13441665 | AM6: 61.942056 | AN6: =AVERAGE(AJ6,AL6) -> 0.10985944 | AO6: =AVERAGE(AK6,AM6) -> 58.874974 | AP6: 0.91460743 | AQ6: 68.062339
A7: 2003 | B7: 0.012050078 | C7: 41.211294 | D7: 0 | E7: 54.188661 | F7: 0 | G7: 59.987558 | H7: 0.00016273281 | I7: 71.781623 | J7: =AVERAGE(D7,F7,H7) -> 5.4244269e-05 | K7: =AVERAGE(E7,G7,I7) -> 61.985947 | L7: 0.015948571 | M7: 84.810286 | N7: 8.2246667e-05 | O7: 112.13848 | P7: =AVERAGE(L7,N7) -> 0.0080154086 | Q7: =AVERAGE(M7,O7) -> 98.474382 | R7: 0.014762462 | S7: 66.203894 | T7: 0.00064460527 | U7: 42.364299 | V7: =AVERAGE(R7,T7) -> 0.0077035335 | W7: =AVERAGE(S7,U7) -> 54.284097 | X7: 0.0068435384 | Y7: 43.151033 | Z7: 0.012553634 | AA7: 67.446408 | AB7: =AVERAGE(X7,Z7) -> 0.009698586 | AC7: =AVERAGE(Y7,AA7) -> 55.29872 | AD7: 0.014825615 | AE7: 34.888582 | AF7: 0.023783056 | AG7: 39.333486 | AH7: =AVERAGE(AD7,AF7) -> 0.019304335 | AI7: =AVERAGE(AE7,AG7) -> 37.111034 | AJ7: 0.046473772 | AK7: 54.805577 | AL7: 0.11290879 | AM7: 57.973675 | AN7: =AVERAGE(AJ7,AL7) -> 0.079691281 | AO7: =AVERAGE(AK7,AM7) -> 56.389626 | AP7: 0.62765087 | AQ7: 66.770101
A8: 2004 | B8: 0.011219617 | C8: 45.658838 | D8: 0 | E8: 58.11977 | F8: 0 | G8: 64.047905 | H8: 0.00016914088 | I8: 79.933963 | J8: =AVERAGE(D8,F8,H8) -> 5.6380293e-05 | K8: =AVERAGE(E8,G8,I8) -> 67.367212 | L8: 0.014193072 | M8: 87.377168 | N8: 6.908816e-05 | O8: 113.11709 | P8: =AVERAGE(L8,N8) -> 0.0071310802 | Q8: =AVERAGE(M8,O8) -> 100.24713 | R8: 38.28977 | S8: 64.106173 | T8: 0.00078104747 | U8: 51.817155 | V8: =AVERAGE(R8,T8) -> 19.145276 | W8: =AVERAGE(S8,U8) -> 57.961664 | X8: 0.0059092727 | Y8: 46.862408 | Z8: 0.011604209 | AA8: 67.380208 | AB8: =AVERAGE(X8,Z8) -> 0.0087567407 | AC8: =AVERAGE(Y8,AA8) -> 57.121308 | AD8: 0.013884468 | AE8: 38.263212 | AF8: 0.024017632 | AG8: 42.200918 | AH8: =AVERAGE(AD8,AF8) -> 0.01895105 | AI8: =AVERAGE(AE8,AG8) -> 40.232065 | AJ8: 0.049659135 | AK8: 60.063539 | AL8: 0.10735287 | AM8: 61.494253 | AN8: =AVERAGE(AJ8,AL8) -> 0.078506004 | AO8: =AVERAGE(AK8,AM8) -> 60.778896 | AP8: 0.47812223 | AQ8: 69.269708
A9: 2005 | B9: 0.010939867 | C9: 32.886266 | D9: 0 | E9: 55.594684 | F9: 0 | G9: 61.785998 | H9: 0.00013690665 | I9: 57.707118 | J9: =AVERAGE(D9,F9,H9) -> 4.5635549e-05 | K9: =AVERAGE(E9,G9,I9) -> 58.3626 | L9: 0.013812841 | M9: 85.081928 | N9: 0.055872508 | O9: 113.38747 | P9: =AVERAGE(L9,N9) -> 0.034842674 | Q9: =AVERAGE(M9,O9) -> 99.234699 | R9: 68.772954 | S9: 68.772954 | T9: 0.00062938479 | U9: 41.221235 | V9: =AVERAGE(R9,T9) -> 34.386792 | W9: =AVERAGE(S9,U9) -> 54.997095 | X9: 0.0070821927 | Y9: 49.637718 | Z9: 0.012557897 | AA9: 67.444033 | AB9: =AVERAGE(X9,Z9) -> 0.0098200451 | AC9: =AVERAGE(Y9,AA9) -> 58.540876 | AD9: 0.016880214 | AE9: 40.668402 | AF9: 0.023784288 | AG9: 39.365481 | AH9: =AVERAGE(AD9,AF9) -> 0.020332251 | AI9: =AVERAGE(AE9,AG9) -> 40.016941 | AJ9: 0.053110429 | AK9: 59.710164 | AL9: 0.13363281 | AM9: 56.155716 | AN9: =AVERAGE(AJ9,AL9) -> 0.093371621 | AO9: =AVERAGE(AK9,AM9) -> 57.93294 | AP9: 2.1628036 | AQ9: 67.622854
A10: 2006 | B10: 0.016033413 | C10: 53.454159 | D10: 0 | E10: 60.330531 | F10: 0 | G10: 63.655058 | H10: 0.00019057549 | I10: 78.771688 | J10: =AVERAGE(D10,F10,H10) -> 6.3525163e-05 | K10: =AVERAGE(E10,G10,I10) -> 67.585759 | L10: 0.017457123 | M10: 88.753524 | N10: 0 | O10: 114.41727 | P10: =AVERAGE(L10,N10) -> 0.0087285616 | Q10: =AVERAGE(M10,O10) -> 101.5854 | R10: 0.02098353 | S10: 65.586104 | T10: 0.00065545909 | U10: 42.914317 | V10: =AVERAGE(R10,T10) -> 0.010819495 | W10: =AVERAGE(S10,U10) -> 54.250211 | X10: 0.0083207343 | Y10: 52.187362 | Z10: 0.012560935 | AA10: 67.459086 | AB10: =AVERAGE(X10,Z10) -> 0.010440835 | AC10: =AVERAGE(Y10,AA10) -> 59.823224 | AD10: 0.01926898 | AE10: 43.86664 | AF10: 0.023779997 | AG10: 39.254009 | AH10: =AVERAGE(AD10,AF10) -> 0.021524489 | AI10: =AVERAGE(AE10,AG10) -> 41.560324 | AJ10: 0.098754202 | AK10: 59.198947 | AL10: 0.17535551 | AM10: 55.977412 | AN10: =AVERAGE(AJ10,AL10) -> 0.13705486 | AO10: =AVERAGE(AK10,AM10) -> 57.588179 | AP10: 1.000075 | AQ10: 67.773965
A11: 2007 | B11: 0.015053944 | C11: 50.469853 | D11: 0 | E11: 57.930713 | F11: 0 | G11: 59.684115 | H11: 0.00014992944 | I11: 75.530877 | J11: =AVERAGE(D11,F11,H11) -> 4.9976478e-05 | K11: =AVERAGE(E11,G11,I11) -> 64.381902 | L11: 0.016353498 | M11: 87.271923 | N11: 0 | O11: 109.875 | P11: =AVERAGE(L11,N11) -> 0.0081767491 | Q11: =AVERAGE(M11,O11) -> 98.57346 | R11: 0.083249299 | S11: 66.274787 | T11: 0.00064431735 | U11: 42.917989 | V11: =AVERAGE(R11,T11) -> 0.041946808 | W11: =AVERAGE(S11,U11) -> 54.596388 | X11: 0.0084161401 | Y11: 49.147288 | Z11: 0.012560935 | AA11: 67.459086 | AB11: =AVERAGE(X11,Z11) -> 0.010488537 | AC11: =AVERAGE(Y11,AA11) -> 58.303187 | AD11: 0.017009025 | AE11: 39.274334 | AF11: 0.023722028 | AG11: 38.795344 | AH11: =AVERAGE(AD11,AF11) -> 0.020365526 | AI11: =AVERAGE(AE11,AG11) -> 39.034839 | AJ11: 0.061910326 | AK11: 60.036843 | AL11: 0.11664792 | AM11: 54.030846 | AN11: =AVERAGE(AJ11,AL11) -> 0.089279126 | AO11: =AVERAGE(AK11,AM11) -> 57.033844 | AP11: 1.1371625 | AQ11: 64.50508
A12: 2008 | B12: 0.014282269 | C12: 52.826287 | D12: 0 | E12: 63.817348 | F12: 0 | G12: 66.0519 | H12: 0.00017488541 | I12: 73.220624 | J12: =AVERAGE(D12,F12,H12) -> 5.8295136e-05 | K12: =AVERAGE(E12,G12,I12) -> 67.696624 | L12: 0.018619787 | M12: 87.912755 | N12: 0 | O12: 108.45058 | P12: =AVERAGE(L12,N12) -> 0.0093098933 | Q12: =AVERAGE(M12,O12) -> 98.181667 | R12: 1.779128e-18 | S12: 65.248725 | T12: 0.00088960797 | U12: 58.003498 | V12: =AVERAGE(R12,T12) -> 0.00044480398 | W12: =AVERAGE(S12,U12) -> 61.626111 | X12: 0.0082262997 | Y12: 55.079728 | Z12: 0.011631648 | AA12: 67.467715 | AB12: =AVERAGE(X12,Z12) -> 0.009928974 | AC12: =AVERAGE(Y12,AA12) -> 61.273721 | AD12: 0.021093718 | AE12: 49.608237 | AF12: 0.024043514 | AG12: 42.294717 | AH12: =AVERAGE(AD12,AF12) -> 0.022568616 | AI12: =AVERAGE(AE12,AG12) -> 45.951477 | AJ12: 0.10772912 | AK12: 59.347237 | AL12: 0.20435007 | AM12: 61.535105 | AN12: =AVERAGE(AJ12,AL12) -> 0.15603959 | AO12: =AVERAGE(AK12,AM12) -> 60.441171 | AP12: 0.85121438 | AQ12: 70.460721
A13: 2009 | B13: 0.014374172 | C13: 50.104984 | D13: 0 | E13: 65.058398 | F13: 0 | G13: 67.391449 | H13: 0.00028074095 | I13: 84.581679 | J13: =AVERAGE(D13,F13,H13) -> 9.3580318e-05 | K13: =AVERAGE(E13,G13,I13) -> 72.343842 | L13: 0.018475576 | M13: 87.27001 | N13: 0 | O13: 109.85533 | P13: =AVERAGE(L13,N13) -> 0.009237788 | Q13: =AVERAGE(M13,O13) -> 98.562671 | R13: 78.184001 | S13: 78.184001 | T13: 0.00062457785 | U13: 42.342482 | V13: =AVERAGE(R13,T13) -> 39.092313 | W13: =AVERAGE(S13,U13) -> 60.263241 | X13: 0.0092043601 | Y13: 53.818138 | Z13: 0.012479063 | AA13: 67.45581 | AB13: =AVERAGE(X13,Z13) -> 0.010841712 | AC13: =AVERAGE(Y13,AA13) -> 60.636974 | AD13: 0.020561577 | AE13: 47.699621 | AF13: 0.023754386 | AG13: 39.270975 | AH13: =AVERAGE(AD13,AF13) -> 0.022157981 | AI13: =AVERAGE(AE13,AG13) -> 43.485298 | AJ13: 0.11097217 | AK13: 60.132335 | AL13: 0.1201687 | AM13: 61.804315 | AN13: =AVERAGE(AJ13,AL13) -> 0.11557043 | AO13: =AVERAGE(AK13,AM13) -> 60.968325 | AP13: 0.78381899 | AQ13: 69.024491
A14: 2010 | B14: 0.01198857 | C14: 43.765024 | D14: 0 | E14: 51.608878 | F14: 0 | G14: 54.144046 | H14: 0.00011818651 | I14: 74.348243 | J14: =AVERAGE(D14,F14,H14) -> 3.9395502e-05 | K14: =AVERAGE(E14,G14,I14) -> 60.033723 | L14: 0.010429005 | M14: 80.048641 | N14: 0 | O14: 110.82724 | P14: =AVERAGE(L14,N14) -> 0.0052145026 | Q14: =AVERAGE(M14,O14) -> 95.437941 | R14: 0.32466488 | S14: 70.361442 | T14: 0.00064291578 | U14: 44.234982 | V14: =AVERAGE(R14,T14) -> 0.1626539 | W14: =AVERAGE(S14,U14) -> 57.298212 | X14: 0.0042792023 | Y14: 39.958858 | Z14: 0.01297318 | AA14: 67.64503 | AB14: =AVERAGE(X14,Z14) -> 0.0086261913 | AC14: =AVERAGE(Y14,AA14) -> 53.801944 | AD14: 0.014717168 | AE14: 33.339811 | AF14: 0.023783056 | AG14: 39.33339 | AH14: =AVERAGE(AD14,AF14) -> 0.019250112 | AI14: =AVERAGE(AE14,AG14) -> 36.3366 | AJ14: 0.041733029 | AK14: 59.138527 | AL14: 0.18199964 | AM14: 45.753493 | AN14: =AVERAGE(AJ14,AL14) -> 0.11186634 | AO14: =AVERAGE(AK14,AM14) -> 52.44601 | AP14: 0.93264238 | AQ14: 68.291287
A15: 2011 | B15: 0.013737581 | C15: 45.644538 | D15: 0 | E15: 68.243293 | F15: 0 | G15: 67.302424 | H15: 0.00024868734 | I15: 84.667123 | J15: =AVERAGE(D15,F15,H15) -> 8.2895779e-05 | K15: =AVERAGE(E15,G15,I15) -> 73.40428 | L15: 0.019999839 | M15: 87.948575 | N15: 0.00010450553 | O15: 108.83335 | P15: =AVERAGE(L15,N15) -> 0.010052172 | Q15: =AVERAGE(M15,O15) -> 98.390964 | R15: 1.7250274 | S15: 84.238279 | T15: 0.00081633882 | U15: 46.321574 | V15: =AVERAGE(R15,T15) -> 0.86292186 | W15: =AVERAGE(S15,U15) -> 65.279927 | X15: 0.010646952 | Y15: 58.161396 | Z15: 0.012566666 | AA15: 67.463783 | AB15: =AVERAGE(X15,Z15) -> 0.011606809 | AC15: =AVERAGE(Y15,AA15) -> 62.812589 | AD15: 0.02074975 | AE15: 48.222833 | AF15: 0.023783056 | AG15: 39.333262 | AH15: =AVERAGE(AD15,AF15) -> 0.022266403 | AI15: =AVERAGE(AE15,AG15) -> 43.778048 | AJ15: 0.11344571 | AK15: 68.458523 | AL15: 0.23610754 | AM15: 59.769421 | AN15: =AVERAGE(AJ15,AL15) -> 0.17477662 | AO15: =AVERAGE(AK15,AM15) -> 64.113972 | AP15: 1.06683 | AQ15: 68.431583
A16: 2012 | B16: 0.01352712 | C16: 50.507036 | D16: 0 | E16: 62.555911 | F16: 0 | G16: 61.358202 | H16: 0.00020851591 | I16: 80.293251 | J16: =AVERAGE(D16,F16,H16) -> 6.9505304e-05 | K16: =AVERAGE(E16,G16,I16) -> 68.069121 | L16: 0.018949218 | M16: 86.399657 | N16: 7.6552003e-05 | O16: 112.08685 | P16: =AVERAGE(L16,N16) -> 0.0095128852 | Q16: =AVERAGE(M16,O16) -> 99.243256 | R16: 0.18822835 | S16: 78.033998 | T16: 0.00057441375 | U16: 44.430523 | V16: =AVERAGE(R16,T16) -> 0.094401381 | W16: =AVERAGE(S16,U16) -> 61.23226 | X16: 0.0088425379 | Y16: 53.319193 | Z16: 0.01231557 | AA16: 67.755182 | AB16: =AVERAGE(X16,Z16) -> 0.010579054 | AC16: =AVERAGE(Y16,AA16) -> 60.537188 | AD16: 0.015256331 | AE16: 40.083615 | AF16: 0.02409343 | AG16: 42.287686 | AH16: =AVERAGE(AD16,AF16) -> 0.019674881 | AI16: =AVERAGE(AE16,AG16) -> 41.18565 | AJ16: 0.13182711 | AK16: 64.83261 | AL16: 0.096034975 | AM16: 56.024993 | AN16: =AVERAGE(AJ16,AL16) -> 0.11393104 | AO16: =AVERAGE(AK16,AM16) -> 60.428802 | AP16: 0.37239704 | AQ16: 67.554867
... A23: 2019 | B23: 0.012914342 | C23: 43.09877 | D23: 0.00010723517 | E23: 53.919374 | F23: 0.00039954105 | G23: 9.5513547 | H23: 0 | I23: 81.522655 | J23: =AVERAGE(D23,F23,H23) -> 0.00016892541 | K23: =AVERAGE(E23,G23,I23) -> 48.331128 | L23: 0 | M23: 85.116721 | N23: 7.4449718e-05 | O23: 112.37942 | P23: =AVERAGE(L23,N23) -> 3.7224859e-05 | Q23: =AVERAGE(M23,O23) -> 98.748069 | R23: 0.083249299 | S23: 66.274787 | T23: 0 | U23: 45.362213 | V23: =AVERAGE(R23,T23) -> 0.041624649 | W23: =AVERAGE(S23,U23) -> 55.8185 | X23: 0.00571837 | Y23: 42.611172 | Z23: 0.012560266 | AA23: 67.458783 | AB23: =AVERAGE(X23,Z23) -> 0.0091393179 | AC23: =AVERAGE(Y23,AA23) -> 55.034978 | AD23: 0.0028228022 | AE23: 36.476151 | AF23: 0.021635294 | AG23: 39.194508 | AH23: =AVERAGE(AD23,AF23) -> 0.012229048 | AI23: =AVERAGE(AE23,AG23) -> 37.83533 | AJ23: 0.054383983 | AK23: 55.543342 | AL23: 0.10441694 | AM23: 54.474274 | AN23: =AVERAGE(AJ23,AL23) -> 0.079400463 | AO23: =AVERAGE(AK23,AM23) -> 55.008808 | AP23: 0.84823662 | AQ23: 68.442106
A24: 2020 | B24: 0.010257127 | C24: 42.099705 | D24: 0 | E24: 57.860322 | F24: 0 | G24: 60.722761 | H24: 0 | I24: 72.223826 | J24: =AVERAGE(D24,F24,H24) -> 0 | K24: =AVERAGE(E24,G24,I24) -> 63.602303 | N24: 7.086064e-05 | O24: 112.29805 | P24: =AVERAGE(L24,N24) -> 7.086064e-05 | Q24: =AVERAGE(M24,O24) -> 112.29805 | R24: 0.062577042 | S24: 66.208491 | T24: 0 | U24: 44.429276 | V24: =AVERAGE(R24,T24) -> 0.031288521 | W24: =AVERAGE(S24,U24) -> 55.318883 | X24: 0.0059016204 | Y24: 43.963396 | Z24: 0.009659257 | AA24: 67.419934 | AB24: =AVERAGE(X24,Z24) -> 0.0077804387 | AC24: =AVERAGE(Y24,AA24) -> 55.691665 | AD24: 0.013235965 | AE24: 39.822587 | AF24: 0.022827236 | AG24: 41.753235 | AH24: =AVERAGE(AD24,AF24) -> 0.018031601 | AI24: =AVERAGE(AE24,AG24) -> 40.787911 | AJ24: 0.038547987 | AK24: 43.672033 | AL24: 0.083101926 | AM24: 56.985021 | AN24: =AVERAGE(AJ24,AL24) -> 0.060824956 | AO24: =AVERAGE(AK24,AM24) -> 50.328527 | AP24: 0.7791339 | AQ24: 68.381479
B26: =B2 -> Córdoba | C26: =J2 -> Guajira | D26: =P2 -> Antioquia | E26: =V2 -> Atlántico | F26: =AB2 -> Magdalena | G26: =AH2 -> Cesar | H26: =AN2 -> Bolívar | I26: =AP2 -> Chocó | L26: =B26 -> Córdoba | M26: =C26 -> Guajira | N26: =D26 -> Antioquia | O26: =E26 -> Atlántico | P26: =F26 -> Magdalena | Q26: =G26 -> Cesar | R26: =H26 -> Bolívar | S26: =I26 -> Chocó
A27: 2000 | B27: =C4 -> 59.697321 | C27: =K4 -> 66.789783 | D27: =Q4 -> 101.03424 | E27: =W4 -> 56.326265 | F27: =AC4 -> 62.176919 | G27: =AI4 -> 49.770737 | H27: =AO4 -> 65.79583 | I27: =AQ4 -> 71.228973 | K27: 2000 | L27: =B4 -> 0.016618811 | M27: =J4 -> 8.0834738e-05 | N27: =P4 -> 0.010007124 | O27: =V4 -> 0.022178794 | P27: =AB4 -> 0.010761874 | Q27: =AH4 -> 0.022548674 | R27: =AN4 -> 0.10054023 | S27: =AP4 -> 1.2498461
A28: 2001 | B28: =C5 -> 56.257969 | C28: =K5 -> 66.141097 | D28: =Q5 -> 100.72544 | E28: =W5 -> 60.089277 | F28: =AC5 -> 62.503089 | G28: =AI5 -> 44.834848 | H28: =AO5 -> 58.057774 | I28: =AQ5 -> 70.098526 | K28: 2001 | L28: =B5 -> 0.015267563 | M28: =J5 -> 6.3427957e-05 | N28: =P5 -> 0.0089303797 | O28: =V5 -> 35.648623 | P28: =AB5 -> 0.011396653 | Q28: =AH5 -> 0.022290376 | R28: =AN5 -> 0.050052884 | S28: =AP5 -> 0.88811914
A29: 2002 | B29: =C6 -> 43.098503 | C29: =K6 -> 68.259266 | D29: =Q6 -> 98.094262 | E29: =W6 -> 59.127781 | F29: =AC6 -> 57.466802 | G29: =AI6 -> 39.742767 | H29: =AO6 -> 58.874974 | I29: =AQ6 -> 68.062339 | K29: 2002 | L29: =B6 -> 0.012132994 | M29: =J6 -> 6.8962478e-05 | N29: =P6 -> 0.0077948415 | O29: =V6 -> 0.033123709 | P29: =AB6 -> 0.0096585878 | Q29: =AH6 -> 0.020237727 | R29: =AN6 -> 0.10985944 | S29: =AP6 -> 0.91460743
A30: 2003 | B30: =C7 -> 41.211294 | C30: =K7 -> 61.985947 | D30: =Q7 -> 98.474382 | E30: =W7 -> 54.284097 | F30: =AC7 -> 55.29872 | G30: =AI7 -> 37.111034 | H30: =AO7 -> 56.389626 | I30: =AQ7 -> 66.770101 | K30: 2003 | L30: =B7 -> 0.012050078 | M30: =J7 -> 5.4244269e-05 | N30: =P7 -> 0.0080154086 | O30: =V7 -> 0.0077035335 | P30: =AB7 -> 0.009698586 | Q30: =AH7 -> 0.019304335 | R30: =AN7 -> 0.079691281 | S30: =AP7 -> 0.62765087
A31: 2004 | B31: =C8 -> 45.658838 | C31: =K8 -> 67.367212 | D31: =Q8 -> 100.24713 | E31: =W8 -> 57.961664 | F31: =AC8 -> 57.121308 | G31: =AI8 -> 40.232065 | H31: =AO8 -> 60.778896 | I31: =AQ8 -> 69.269708 | K31: 2004 | L31: =B8 -> 0.011219617 | M31: =J8 -> 5.6380293e-05 | N31: =P8 -> 0.0071310802 | O31: =V8 -> 19.145276 | P31: =AB8 -> 0.0087567407 | Q31: =AH8 -> 0.01895105 | R31: =AN8 -> 0.078506004 | S31: =AP8 -> 0.47812223
A32: 2005 | B32: =C9 -> 32.886266 | C32: =K9 -> 58.3626 | D32: =Q9 -> 99.234699 | E32: =W9 -> 54.997095 | F32: =AC9 -> 58.540876 | G32: =AI9 -> 40.016941 | H32: =AO9 -> 57.93294 | I32: =AQ9 -> 67.622854 | K32: 2005 | L32: =B9 -> 0.010939867 | M32: =J9 -> 4.5635549e-05 | N32: =P9 -> 0.034842674 | O32: =V9 -> 34.386792 | P32: =AB9 -> 0.0098200451 | Q32: =AH9 -> 0.020332251 | R32: =AN9 -> 0.093371621 | S32: =AP9 -> 2.1628036
A33: 2006 | B33: =C10 -> 53.454159 | C33: =K10 -> 67.585759 | D33: =Q10 -> 101.5854 | E33: =W10 -> 54.250211 | F33: =AC10 -> 59.823224 | G33: =AI10 -> 41.560324 | H33: =AO10 -> 57.588179 | I33: =AQ10 -> 67.773965 | K33: 2006 | L33: =B10 -> 0.016033413 | M33: =J10 -> 6.3525163e-05 | N33: =P10 -> 0.0087285616 | O33: =V10 -> 0.010819495 | P33: =AB10 -> 0.010440835 | Q33: =AH10 -> 0.021524489 | R33: =AN10 -> 0.13705486 | S33: =AP10 -> 1.000075
A34: 2007 | B34: =C11 -> 50.469853 | C34: =K11 -> 64.381902 | D34: =Q11 -> 98.57346 | E34: =W11 -> 54.596388 | F34: =AC11 -> 58.303187 | G34: =AI11 -> 39.034839 | H34: =AO11 -> 57.033844 | I34: =AQ11 -> 64.50508 | K34: 2007 | L34: =B11 -> 0.015053944 | M34: =J11 -> 4.9976478e-05 | N34: =P11 -> 0.0081767491 | O34: =V11 -> 0.041946808 | P34: =AB11 -> 0.010488537 | Q34: =AH11 -> 0.020365526 | R34: =AN11 -> 0.089279126 | S34: =AP11 -> 1.1371625
A35: 2008 | B35: =C12 -> 52.826287 | C35: =K12 -> 67.696624 | D35: =Q12 -> 98.181667 | E35: =W12 -> 61.626111 | F35: =AC12 -> 61.273721 | G35: =AI12 -> 45.951477 | H35: =AO12 -> 60.441171 | I35: =AQ12 -> 70.460721 | K35: 2008 | L35: =B12 -> 0.014282269 | M35: =J12 -> 5.8295136e-05 | N35: =P12 -> 0.0093098933 | O35: =V12 -> 0.00044480398 | P35: =AB12 -> 0.009928974 | Q35: =AH12 -> 0.022568616 | R35: =AN12 -> 0.15603959 | S35: =AP12 -> 0.85121438
A36: 2009 | B36: =C13 -> 50.104984 | C36: =K13 -> 72.343842 | D36: =Q13 -> 98.562671 | E36: =W13 -> 60.263241 | F36: =AC13 -> 60.636974 | G36: =AI13 -> 43.485298 | H36: =AO13 -> 60.968325 | I36: =AQ13 -> 69.024491 | K36: 2009 | L36: =B13 -> 0.014374172 | M36: =J13 -> 9.3580318e-05 | N36: =P13 -> 0.009237788 | O36: =V13 -> 39.092313 | P36: =AB13 -> 0.010841712 | Q36: =AH13 -> 0.022157981 | R36: =AN13 -> 0.11557043 | S36: =AP13 -> 0.78381899
A37: 2010 | B37: =C14 -> 43.765024 | C37: =K14 -> 60.033723 | D37: =Q14 -> 95.437941 | E37: =W14 -> 57.298212 | F37: =AC14 -> 53.801944 | G37: =AI14 -> 36.3366 | H37: =AO14 -> 52.44601 | I37: =AQ14 -> 68.291287 | K37: 2010 | L37: =B14 -> 0.01198857 | M37: =J14 -> 3.9395502e-05 | N37: =P14 -> 0.0052145026 | O37: =V14 -> 0.1626539 | P37: =AB14 -> 0.0086261913 | Q37: =AH14 -> 0.019250112 | R37: =AN14 -> 0.11186634 | S37: =AP14 -> 0.93264238
A38: 2011 | B38: =C15 -> 45.644538 | C38: =K15 -> 73.40428 | D38: =Q15 -> 98.390964 | E38: =W15 -> 65.279927 | F38: =AC15 -> 62.812589 | G38: =AI15 -> 43.778048 | H38: =AO15 -> 64.113972 | I38: =AQ15 -> 68.431583 | K38: 2011 | L38: =B15 -> 0.013737581 | M38: =J15 -> 8.2895779e-05 | N38: =P15 -> 0.010052172 | O38: =V15 -> 0.86292186 | P38: =AB15 -> 0.011606809 | Q38: =AH15 -> 0.022266403 | R38: =AN15 -> 0.17477662 | S38: =AP15 -> 1.06683
... A47: 2020 | B47: =C24 -> 42.099705 | C47: =K24 -> 63.602303 | D47: =Q24 -> 112.29805 | E47: =W24 -> 55.318883 | F47: =AC24 -> 55.691665 | G47: =AI24 -> 40.787911 | H47: =AO24 -> 50.328527 | I47: =AQ24 -> 68.381479 | K47: 2020 | L47: =B24 -> 0.010257127 | M47: =J24 -> 0 | N47: =P24 -> 7.086064e-05 | O47: =V24 -> 0.031288521 | P47: =AB24 -> 0.0077804387 | Q47: =AH24 -> 0.018031601 | R47: =AN24 -> 0.060824956 | S47: =AP24 -> 0.7791339
A48: Promedio | B48: =AVERAGE(B27:B47) -> 46.537345 | C48: =AVERAGE(C27:C47) -> 64.389292 | D48: =AVERAGE(D27:D47) -> 99.755887 | E48: =AVERAGE(E27:E47) -> 59.841818 | F48: =AVERAGE(F27:F47) -> 57.790718 | G48: =AVERAGE(G27:G47) -> 40.456291 | H48: =AVERAGE(H27:H47) -> 57.479362 | I48: =AVERAGE(I27:I47) -> 68.284682 | K48: Promedio | L48: =AVERAGE(L27:L47) -> 0.01306468 | M48: =AVERAGE(M27:M47) -> 0.00021401933 | N48: =AVERAGE(N27:N47) -> 0.014189648 | O48: =AVERAGE(O27:O47) -> 10.23045 | P48: =AVERAGE(P27:P47) -> 0.010225387 | Q48: =AVERAGE(Q27:Q47) -> 0.019882046 | R48: =AVERAGE(R27:R47) -> 0.099211492 | S48: =AVERAGE(S27:S47) -> 0.87865234
A49: Minimo | B49: =MIN(B27:B47) -> 32.886266 | C49: =MIN(C27:C47) -> 48.331128 | D49: =MIN(D27:D47) -> 95.437941 | E49: =MIN(E27:E47) -> 47.64611 | F49: =MIN(F27:F47) -> 52.419879 | G49: =MIN(G27:G47) -> 35.895838 | H49: =MIN(H27:H47) -> 47.797227 | I49: =MIN(I27:I47) -> 64.50508 | K49: Minimo | L49: =MIN(L27:L47) -> 0.010257127 | M49: =MIN(M27:M47) -> 0 | N49: =MIN(N27:N47) -> 3.7224859e-05 | O49: =MIN(O27:O47) -> 0.00029170872 | P49: =MIN(P27:P47) -> 0.0077804387 | Q49: =MIN(Q27:Q47) -> 0.012229048 | R49: =MIN(R27:R47) -> 0.050052884 | S49: =MIN(S27:S47) -> 0.30902956
A50: Maximo | B50: =MAX(B27:B47) -> 59.697321 | C50: =MAX(C27:C47) -> 73.40428 | D50: =MAX(D27:D47) -> 112.29805 | E50: =MAX(E27:E47) -> 110.122 | F50: =MAX(F27:F47) -> 62.812589 | G50: =MAX(G27:G47) -> 49.770737 | H50: =MAX(H27:H47) -> 65.79583 | I50: =MAX(I27:I47) -> 71.228973 | K50: Maximo | L50: =MAX(L27:L47) -> 0.016618811 | M50: =MAX(M27:M47) -> 0.0026887017 | N50: =MAX(N27:N47) -> 0.086897673 | O50: =MAX(O27:O47) -> 85.140814 | P50: =MAX(P27:P47) -> 0.019699483 | Q50: =MAX(Q27:Q47) -> 0.022568616 | R50: =MAX(R27:R47) -> 0.17477662 | S50: =MAX(S27:S47) -> 2.1628036
L67: NO SE VE BIEN

Sheet Resumen_Cordoba1
A1: Hoja | B1: Station Number | C1: Año | D1: Día | E1: Irradiacion | F1: Min Temp | G1: Max Temp | H1: Temp Promedio | I1: Vapor | J1: Wind Speed | K1: Precipitacion | L1: Departamento | M1: Irrigacion | N1: Produccion | O1: Toneladas por hectaria
A2: 2000 | B2: 1 | C2: 2000 | D2: 183.5 | E2: 4593.1 | F2: 23.34 | G2: 32.93 | H2: 28.14 | I2: 38.22 | J2: 1.05 | K2: 5.83 | L2: 1 | M2: 1 | N2: {=TRANSPOSE('1_2000_2020'!B273:AQ273)} -> 5969.7321 | O2: =N2*0.01 -> 59.697321
A3: 2001 | B3: 1 | C3: 2001 | D3: 183 | E3: 4591.66 | F3: 23.84 | G3: 33.27 | H3: 28.56 | I3: 39.24 | J3: 1.09 | K3: 5.84 | L3: 1 | M3: 1 | N3: 5625.7969 | O3: =N3*0.01 -> 56.257969
A4: 2002 | B4: 1 | C4: 2002 | D4: 183 | E4: 4591.66 | F4: 24.13 | G4: 33.74 | H4: 28.94 | I4: 40.13 | J4: 0.94 | K4: 5.84 | L4: 1 | M4: 1 | N4: 4309.8503 | O4: =N4*0.01 -> 43.098503
A5: 2003 | B5: 1 | C5: 2003 | D5: 183 | E5: 4591.66 | F5: 24.08 | G5: 33.28 | H5: 28.68 | I5: 39.5 | J5: 1.11 | K5: 5.84 | L5: 1 | M5: 1 | N5: 4121.1294 | O5: =N5*0.01 -> 41.211294
A6: 2004 | B6: 1 | C6: 2004 | D6: 183.5 | E6: 4593.1 | F6: 24.4 | G6: 33.39 | H6: 28.9 | I6: 40.11 | J6: 1.05 | K6: 5.83 | L6: 1 | M6: 1 | N6: 4565.8838 | O6: =N6*0.01 -> 45.658838
A7: 2005 | B7: 1 | C7: 2005 | D7: 183 | E7: 4591.66 | F7: 24.54 | G7: 33.14 | H7: 28.84 | I7: 39.98 | J7: 0.86 | K7: 5.84 | L7: 1 | M7: 1 | N7: 3288.6266 | O7: =N7*0.01 -> 32.886266
A8: 2006 | B8: 1 | C8: 2006 | D8: 183 | E8: 4591.66 | F8: 23.3 | G8: 33.4 | H8: 28.35 | I8: 38.66 | J8: 0.76 | K8: 5.84 | L8: 1 | M8: 1 | N8: 5345.4159 | O8: =N8*0.01 -> 53.454159
A9: 2007 | B9: 1 | C9: 2007 | D9: 183 | E9: 4591.66 | F9: 23.87 | G9: 33.25 | H9: 28.56 | I9: 39.22 | J9: 0.93 | K9: 5.84 | L9: 1 | M9: 1 | N9: 5046.9853 | O9: =N9*0.01 -> 50.469853
A10: 2008 | B10: 1 | C10: 2008 | D10: 183.5 | E10: 4593.1 | F10: 24.16 | G10: 33.18 | H10: 28.67 | I10: 39.58 | J10: 0.9 | K10: 5.83 | L10: 1 | M10: 1 | N10: 5282.6287 | O10: =N10*0.01 -> 52.826287
A11: 2009 | B11: 1 | C11: 2009 | D11: 183 | E11: 4591.66 | F11: 24.72 | G11: 33.65 | H11: 29.19 | I11: 40.79 | J11: 0.82 | K11: 5.84 | L11: 1 | M11: 1 | N11: 5010.4984 | O11: =N11*0.01 -> 50.104984
A12: 2010 | B12: 1 | C12: 2010 | D12: 183 | E12: 4591.66 | F12: 24.78 | G12: 32.97 | H12: 28.88 | I12: 40.05 | J12: 0.85 | K12: 5.84 | L12: 1 | M12: 1 | N12: 4376.5024 | O12: =N12*0.01 -> 43.765024
A13: 2011 | B13: 1 | C13: 2011 | D13: 183 | E13: 4591.66 | F13: 24.7 | G13: 32.84 | H13: 28.77 | I13: 39.81 | J13: 0.82 | K13: 5.84 | L13: 1 | M13: 1 | N13: 4564.4538 | O13: =N13*0.01 -> 45.644538
A14: 2012 | B14: 1 | C14: 2012 | D14: 183.5 | E14: 4593.1 | F14: 24.64 | G14: 33.2 | H14: 28.92 | I14: 40.1 | J14: 1.01 | K14: 5.83 | L14: 1 | M14: 1 | N14: 5050.7036 | O14: =N14*0.01 -> 50.507036
... A22: 2020 | B22: 1 | C22: 2020 | D22: 183.5 | E22: 4612.74 | F22: 23.89 | G22: 33.94 | H22: 28.92 | I22: 39.96 | J22: 0.95 | K22: 6.03 | L22: 1 | M22: 1 | N22: 4209.9705 | O22: =N22*0.01 -> 42.099705
A23: =A2 -> 2000 | B23: =B2 -> 1 | C23: =C2 -> 2000 | D23: =D2 -> 183.5 | E23: =E2 -> 4593.1 | F23: =F2 -> 23.34 | G23: =G2 -> 32.93 | H23: =H2 -> 28.14 | ... L23: =L2 -> 1 | M23: 0 | N23: 1.6618811 | O23: =N23*0.01 -> 0.016618811
A24: =A3 -> 2001 | B24: =B3 -> 1 | C24: =C3 -> 2001 | D24: =D3 -> 183 | E24: =E3 -> 4591.66 | F24: =F3 -> 23.84 | G24: =G3 -> 33.27 | H24: =H3 -> 28.56 | ... L24: =L3 -> 1 | M24: 0 | N24: 1.5267563 | O24: =N24*0.01 -> 0.015267563
A25: =A4 -> 2002 | B25: =B4 -> 1 | C25: =C4 -> 2002 | D25: =D4 -> 183 | E25: =E4 -> 4591.66 | F25: =F4 -> 24.13 | G25: =G4 -> 33.74 | H25: =H4 -> 28.94 | ... L25: =L4 -> 1 | M25: 0 | N25: 1.2132994 | O25: =N25*0.01 -> 0.012132994
A26: =A5 -> 2003 | B26: =B5 -> 1 | C26: =C5 -> 2003 | D26: =D5 -> 183 | E26: =E5 -> 4591.66 | F26: =F5 -> 24.08 | G26: =G5 -> 33.28 | H26: =H5 -> 28.68 | ... L26: =L5 -> 1 | M26: 0 | N26: 1.2050078 | O26: =N26*0.01 -> 0.012050078
A27: =A6 -> 2004 | B27: =B6 -> 1 | C27: =C6 -> 2004 | D27: =D6 -> 183.5 | E27: =E6 -> 4593.1 | F27: =F6 -> 24.4 | G27: =G6 -> 33.39 | H27: =H6 -> 28.9 | ... L27: =L6 -> 1 | M27: 0 | N27: 1.1219617 | O27: =N27*0.01 -> 0.011219617
A28: =A7 -> 2005 | B28: =B7 -> 1 | C28: =C7 -> 2005 | D28: =D7 -> 183 | E28: =E7 -> 4591.66 | F28: =F7 -> 24.54 | G28: =G7 -> 33.14 | H28: =H7 -> 28.84 | ... L28: =L7 -> 1 | M28: 0 | N28: 1.0939867 | O28: =N28*0.01 -> 0.010939867
A29: =A8 -> 2006 | B29: =B8 -> 1 | C29: =C8 -> 2006 | D29: =D8 -> 183 | E29: =E8 -> 4591.66 | F29: =F8 -> 23.3 | G29: =G8 -> 33.4 | H29: =H8 -> 28.35 | ... L29: =L8 -> 1 | M29: 0 | N29: 1.6033413 | O29: =N29*0.01 -> 0.016033413
A30: =A9 -> 2007 | B30: =B9 -> 1 | C30: =C9 -> 2007 | D30: =D9 -> 183 | E30: =E9 -> 4591.66 | F30: =F9 -> 23.87 | G30: =G9 -> 33.25 | H30: =H9 -> 28.56 | ... L30: =L9 -> 1 | M30: 0 | N30: 1.5053944 | O30: =N30*0.01 -> 0.015053944
A31: =A10 -> 2008 | B31: =B10 -> 1 | C31: =C10 -> 2008 | D31: =D10 -> 183.5 | E31: =E10 -> 4593.1 | F31: =F10 -> 24.16 | G31: =G10 -> 33.18 | H31: =H10 -> 28.67 | ... L31: =L10 -> 1 | M31: 0 | N31: 1.4282269 | O31: =N31*0.01 -> 0.014282269
A32: =A11 -> 2009 | B32: =B11 -> 1 | C32: =C11 -> 2009 | D32: =D11 -> 183 | E32: =E11 -> 4591.66 | F32: =F11 -> 24.72 | G32: =G11 -> 33.65 | H32: =H11 -> 29.19 | ... L32: =L11 -> 1 | M32: 0 | N32: 1.4374172 | O32: =N32*0.01 -> 0.014374172
A33: =A12 -> 2010 | B33: =B12 -> 1 | C33: =C12 -> 2010 | D33: =D12 -> 183 | E33: =E12 -> 4591.66 | F33: =F12 -> 24.78 | G33: =G12 -> 32.97 | H33: =H12 -> 28.88 | ... L33: =L12 -> 1 | M33: 0 | N33: 1.198857 | O33: =N33*0.01 -> 0.01198857
A34: =A13 -> 2011 | B34: =B13 -> 1 | C34: =C13 -> 2011 | D34: =D13 -> 183 | E34: =E13 -> 4591.66 | F34: =F13 -> 24.7 | G34: =G13 -> 32.84 | H34: =H13 -> 28.77 | ... L34: =L13 -> 1 | M34: 0 | N34: 1.3737581 | O34: =N34*0.01 -> 0.013737581
... A43: =A22 -> 2020 | B43: =B22 -> 1 | C43: =C22 -> 2020 | D43: =D22 -> 183.5 | E43: =E22 -> 4612.74 | F43: =F22 -> 23.89 | G43: =G22 -> 33.94 | H43: =H22 -> 28.92 | ... L43: =L22 -> 1 | M43: 0 | N43: 1.0257127 | O43: =N43*0.01 -> 0.010257127

Sheet Resumen_Guajira2
A1: Hoja | B1: Station Number | C1: Año | D1: Día | E1: Irradiacion | F1: Min Temp | G1: Max Temp | H1: Temp Promedio | I1: Vapor | J1: Wind Speed | K1: Precipitacion | L1: Departamento | M1: Irrigacion | N1: Produccion | O1: Toneladas por hectaria
A2: 2000 | B2: 2 | C2: 2000 | D2: 183.5 | E2: 5525.98 | F2: 24.11 | G2: 33.7 | H2: 28.9 | I2: 40.08 | J2: 2.8 | K2: 0.76 | L2: 2 | M2: 1 | N2: {=TRANSPOSE('2_2000_2020'!B273:AQ273)} -> 6257.5948 | O2: =N2*0.01 -> 62.575948
A3: 2001 | B3: 2 | C3: 2001 | D3: 183 | E3: 5523.94 | F3: 24.42 | G3: 33.45 | H3: 28.93 | I3: 40.06 | J3: 2.87 | K3: 0.77 | L3: 2 | M3: 1 | N3: 6227.1139 | O3: =N3*0.01 -> 62.271139
A4: 2002 | B4: 2 | C4: 2002 | D4: 183 | E4: 5523.94 | F4: 24.77 | G4: 33.53 | H4: 29.15 | I4: 40.56 | J4: 3.27 | K4: 0.77 | L4: 2 | M4: 1 | N4: 6030.1063 | O4: =N4*0.01 -> 60.301063
A5: 2003 | B5: 2 | C5: 2003 | D5: 183 | E5: 5523.94 | F5: 24.64 | G5: 33.47 | H5: 29.06 | I5: 40.38 | J5: 2.82 | K5: 0.77 | L5: 2 | M5: 1 | N5: 5418.8661 | O5: =N5*0.01 -> 54.188661
A6: 2004 | B6: 2 | C6: 2004 | D6: 183.5 | E6: 5525.98 | F6: 24.56 | G6: 33.39 | H6: 28.97 | I6: 40.12 | J6: 2.77 | K6: 0.77 | L6: 2 | M6: 1 | N6: 5811.977 | O6: =N6*0.01 -> 58.11977
A7: 2005 | B7: 2 | C7: 2005 | D7: 183 | E7: 5523.94 | F7: 24.25 | G7: 33.4 | H7: 28.83 | I7: 39.87 | J7: 2.12 | K7: 0.77 | L7: 2 | M7: 1 | N7: 5559.4684 | O7: =N7*0.01 -> 55.594684
A8: 2006 | B8: 2 | C8: 2006 | D8: 183 | E8: 5523.94 | F8: 24.06 | G8: 33.45 | H8: 28.76 | I8: 39.66 | J8: 2.56 | K8: 0.77 | L8: 2 | M8: 1 | N8: 6033.0531 | O8: =N8*0.01 -> 60.330531
A9: 2007 | B9: 2 | C9: 2007 | D9: 183 | E9: 5458.67 | F9: 24 | G9: 33.11 | H9: 28.55 | I9: 39.13 | J9: 2.36 | K9: 0.77 | L9: 2 | M9: 1 | N9: 5793.0713 | O9: =N9*0.01 -> 57.930713
A10: 2008 | B10: 2 | C10: 2008 | D10: 183.5 | E10: 5353.67 | F10: 23.17 | G10: 33.03 | H10: 28.1 | I10: 38.21 | J10: 1.99 | K10: 0.77 | L10: 2 | M10: 1 | N10: 6381.7348 | O10: =N10*0.01 -> 63.817348
A11: 2009 | B11: 2 | C11: 2009 | D11: 183 | E11: 5480.42 | F11: 24.32 | G11: 33.81 | H11: 29.06 | I11: 40.4 | J11: 2.67 | K11: 0.77 | L11: 2 | M11: 1 | N11: 6505.8398 | O11: =N11*0.01 -> 65.058398
A12: 2010 | B12: 2 | C12: 2010 | D12: 183 | E12: 4997.77 | F12: 24.44 | G12: 32.66 | H12: 28.55 | I12: 39.18 | J12: 2.01 | K12: 0.77 | L12: 2 | M12: 1 | N12: 5160.8878 | O12: =N12*0.01 -> 51.608878
A13: 2011 | B13: 2 | C13: 2011 | D13: 183 | E13: 5302.32 | F13: 23.73 | G13: 32.37 | H13: 28.05 | I13: 38.06 | J13: 2.03 | K13: 0.77 | L13: 2 | M13: 1 | N13: 6824.3293 | O13: =N13*0.01 -> 68.243293
A14: 2012 | B14: 2 | C14: 2012 | D14: 183.5 | E14: 5333.57 | F14: 24.03 | G14: 33.51 | H14: 28.77 | I14: 39.7 | J14: 2.47 | K14: 0.77 | L14: 2 | M14: 1 | N14: 6255.5911 | O14: =N14*0.01 -> 62.555911
... A22: 2020 | B22: 2 | C22: 2020 | D22: 183.5 | E22: 5530.11 | F22: 24.6 | G22: 33.45 | H22: 29.02 | I22: 40.21 | J22: 2.73 | K22: 1.49 | L22: 2 | M22: 1 | N22: 5786.0322 | O22: =N22*0.01 -> 57.860322
A23: =A2 -> 2000 | B23: =B2 -> 2 | C23: =C2 -> 2000 | D23: =D2 -> 183.5 | E23: =E2 -> 5525.98 | F23: =F2 -> 24.11 | G23: =G2 -> 33.7 | H23: =H2 -> 28.9 | ... L23: =L2 -> 2 | M23: 0 | N23: 0 | O23: =N23*0.01 -> 0
A24: =A3 -> 2001 | B24: =B3 -> 2 | C24: =C3 -> 2001 | D24: =D3 -> 183 | E24: =E3 -> 5523.94 | F24: =F3 -> 24.42 | G24: =G3 -> 33.45 | H24: =H3 -> 28.93 | ... L24: =L3 -> 2 | M24: 0 | N24: 0 | O24: =N24*0.01 -> 0
A25: =A4 -> 2002 | B25: =B4 -> 2 | C25: =C4 -> 2002 | D25: =D4 -> 183 | E25: =E4 -> 5523.94 | F25: =F4 -> 24.77 | G25: =G4 -> 33.53 | H25: =H4 -> 29.15 | ... L25: =L4 -> 2 | M25: 0 | N25: 0 | O25: =N25*0.01 -> 0
A26: =A5 -> 2003 | B26: =B5 -> 2 | C26: =C5 -> 2003 | D26: =D5 -> 183 | E26: =E5 -> 5523.94 | F26: =F5 -> 24.64 | G26: =G5 -> 33.47 | H26: =H5 -> 29.06 | ... L26: =L5 -> 2 | M26: 0 | N26: 0 | O26: =N26*0.01 -> 0
A27: =A6 -> 2004 | B27: =B6 -> 2 | C27: =C6 -> 2004 | D27: =D6 -> 183.5 | E27: =E6 -> 5525.98 | F27: =F6 -> 24.56 | G27: =G6 -> 33.39 | H27: =H6 -> 28.97 | ... L27: =L6 -> 2 | M27: 0 | N27: 0 | O27: =N27*0.01 -> 0
A28: =A7 -> 2005 | B28: =B7 -> 2 | C28: =C7 -> 2005 | D28: =D7 -> 183 | E28: =E7 -> 5523.94 | F28: =F7 -> 24.25 | G28: =G7 -> 33.4 | H28: =H7 -> 28.83 | ... L28: =L7 -> 2 | M28: 0 | N28: 0 | O28: =N28*0.01 -> 0
A29: =A8 -> 2006 | B29: =B8 -> 2 | C29: =C8 -> 2006 | D29: =D8 -> 183 | E29: =E8 -> 5523.94 | F29: =F8 -> 24.06 | G29: =G8 -> 33.45 | H29: =H8 -> 28.76 | ... L29: =L8 -> 2 | M29: 0 | N29: 0 | O29: =N29*0.01 -> 0
A30: =A9 -> 2007 | B30: =B9 -> 2 | C30: =C9 -> 2007 | D30: =D9 -> 183 | E30: =E9 -> 5458.67 | F30: =F9 -> 24 | G30: =G9 -> 33.11 | H30: =H9 -> 28.55 | ... L30: =L9 -> 2 | M30: 0 | N30: 0 | O30: =N30*0.01 -> 0
A31: =A10 -> 2008 | B31: =B10 -> 2 | C31: =C10 -> 2008 | D31: =D10 -> 183.5 | E31: =E10 -> 5353.67 | F31: =F10 -> 23.17 | G31: =G10 -> 33.03 | H31: =H10 -> 28.1 | ... L31: =L10 -> 2 | M31: 0 | N31: 0 | O31: =N31*0.01 -> 0
A32: =A11 -> 2009 | B32: =B11 -> 2 | C32: =C11 -> 2009 | D32: =D11 -> 183 | E32: =E11 -> 5480.42 | F32: =F11 -> 24.32 | G32: =G11 -> 33.81 | H32: =H11 -> 29.06 | ... L32: =L11 -> 2 | M32: 0 | N32: 0 | O32: =N32*0.01 -> 0
A33: =A12 -> 2010 | B33: =B12 -> 2 | C33: =C12 -> 2010 | D33: =D12 -> 183 | E33: =E12 -> 4997.77 | F33: =F12 -> 24.44 | G33: =G12 -> 32.66 | H33: =H12 -> 28.55 | ... L33: =L12 -> 2 | M33: 0 | N33: 0 | O33: =N33*0.01 -> 0
A34: =A13 -> 2011 | B34: =B13 -> 2 | C34: =C13 -> 2011 | D34: =D13 -> 183 | E34: =E13 -> 5302.32 | F34: =F13 -> 23.73 | G34: =G13 -> 32.37 | H34: =H13 -> 28.05 | ... L34: =L13 -> 2 | M34: 0 | N34: 0 | O34: =N34*0.01 -> 0
... A43: =A22 -> 2020 | B43: =B22 -> 2 | C43: =C22 -> 2020 | D43: =D22 -> 183.5 | E43: =E22 -> 5530.11 | F43: =F22 -> 24.6 | G43: =G22 -> 33.45 | H43: =H22 -> 29.02 | ... L43: =L22 -> 2 | M43: 0 | N43: 0 | O43: =N43*0.01 -> 0

Sheet Resumen_Guajira3
A1: Hoja | B1: Station Number | C1: Año | D1: Día | E1: Irradiacion | F1: Min Temp | G1: Max Temp | H1: Temp Promedio | I1: Vapor | J1: Wind Speed | K1: Precipitacion | L1: Departamento | M1: Irrigacion | N1: Produccion | O1: Toneladas por hectaria
A2: 2000 | B2: 3 | C2: 2000 | D2: 183.5 | E2: 4514.7 | F2: 25.6 | G2: 32.59 | H2: 29.1 | I2: 40.43 | J2: 6.12 | K2: 0.39 | L2: 2 | M2: 1 | N2: {=TRANSPOSE('3_2000_2020'!B273:AQ273)} -> 7224.8168 | O2: =N2*0.01 -> 72.248168
A3: 2001 | B3: 3 | C3: 2001 | D3: 183 | E3: 4511.64 | F3: 25.84 | G3: 33.04 | H3: 29.44 | I3: 41.21 | J3: 6.92 | K3: 0.39 | L3: 2 | M3: 1 | N3: 6942.748 | O3: =N3*0.01 -> 69.42748
A4: 2002 | B4: 3 | C4: 2002 | D4: 183 | E4: 4511.64 | F4: 26.1 | G4: 33.3 | H4: 29.7 | I4: 41.79 | J4: 6.86 | K4: 0.39 | L4: 2 | M4: 1 | N4: 6153.2176 | O4: =N4*0.01 -> 61.532176
A5: 2003 | B5: 3 | C5: 2003 | D5: 183 | E5: 4511.64 | F5: 26.1 | G5: 33.25 | H5: 29.68 | I5: 41.75 | J5: 6.36 | K5: 0.39 | L5: 2 | M5: 1 | N5: 5998.7558 | O5: =N5*0.01 -> 59.987558
A6: 2004 | B6: 3 | C6: 2004 | D6: 183.5 | E6: 4514.7 | F6: 25.6 | G6: 32.56 | H6: 29.08 | I6: 40.38 | J6: 6.03 | K6: 0.39 | L6: 2 | M6: 1 | N6: 6404.7905 | O6: =N6*0.01 -> 64.047905
A7: 2005 | B7: 3 | C7: 2005 | D7: 183 | E7: 4511.64 | F7: 25.83 | G7: 32.7 | H7: 29.26 | I7: 40.84 | J7: 4.94 | K7: 0.39 | L7: 2 | M7: 1 | N7: 6178.5998 | O7: =N7*0.01 -> 61.785998
A8: 2006 | B8: 3 | C8: 2006 | D8: 183 | E8: 4511.64 | F8: 26.24 | G8: 33.25 | H8: 29.74 | I8: 41.96 | J8: 5.69 | K8: 0.39 | L8: 2 | M8: 1 | N8: 6365.5058 | O8: =N8*0.01 -> 63.655058
A9: 2007 | B9: 3 | C9: 2007 | D9: 183 | E9: 4511.64 | F9: 25.7 | G9: 32.76 | H9: 29.23 | I9: 40.71 | J9: 5.14 | K9: 0.39 | L9: 2 | M9: 1 | N9: 5968.4115 | O9: =N9*0.01 -> 59.684115
A10: 2008 | B10: 3 | C10: 2008 | D10: 183.5 | E10: 4514.7 | F10: 25.54 | G10: 32.39 | H10: 28.97 | I10: 40.12 | J10: 5.31 | K10: 0.39 | L10: 2 | M10: 1 | N10: 6605.19 | O10: =N10*0.01 -> 66.0519
A11: 2009 | B11: 3 | C11: 2009 | D11: 183 | E11: 4511.64 | F11: 26.11 | G11: 33.18 | H11: 29.64 | I11: 41.72 | J11: 5.99 | K11: 0.39 | L11: 2 | M11: 1 | N11: 6739.1449 | O11: =N11*0.01 -> 67.391449
A12: 2010 | B12: 3 | C12: 2010 | D12: 183 | E12: 4511.64 | F12: 25.73 | G12: 32.41 | H12: 29.07 | I12: 40.33 | J12: 4.84 | K12: 0.39 | L12: 2 | M12: 1 | N12: 5414.4046 | O12: =N12*0.01 -> 54.144046
A13: 2011 | B13: 3 | C13: 2011 | D13: 183 | E13: 4511.64 | F13: 25.04 | G13: 32.79 | H13: 28.91 | I13: 39.97 | J13: 4.9 | K13: 0.39 | L13: 2 | M13: 1 | N13: 6730.2424 | O13: =N13*0.01 -> 67.302424
A14: 2012 | B14: 3 | C14: 2012 | D14: 183.5 | E14: 4514.7 | F14: 25.72 | G14: 33.49 | H14: 29.6 | I14: 41.61 | J14: 5.33 | K14: 0.39 | L14: 2 | M14: 1 | N14: 6135.8202 | O14: =N14*0.01 -> 61.358202
... A22: 2020 | B22: 3 | C22: 2020 | D22: 183.5 | E22: 4368.14 | F22: 25.43 | G22: 33.82 | H22: 29.63 | I22: 41.63 | J22: 5.72 | K22: 0.15 | L22: 2 | M22: 1 | N22: 6072.2761 | O22: =N22*0.01 -> 60.722761
A23: =A2 -> 2000 | B23: =B2 -> 3 | C23: =C2 -> 2000 | D23: =D2 -> 183.5 | E23: =E2 -> 4514.7 | F23: =F2 -> 25.6 | G23: =G2 -> 32.59 | H23: =H2 -> 29.1 | ... L23: =L2 -> 2 | M23: 0 | N23: 0 | O23: =N23*0.01 -> 0
A24: =A3 -> 2001 | B24: =B3 -> 3 | C24: =C3 -> 2001 | D24: =D3 -> 183 | E24: =E3 -> 4511.64 | F24: =F3 -> 25.84 | G24: =G3 -> 33.04 | H24: =H3 -> 29.44 | ... L24: =L3 -> 2 | M24: 0 | N24: 0 | O24: =N24*0.01 -> 0
A25: =A4 -> 2002 | B25: =B4 -> 3 | C25: =C4 -> 2002 | D25: =D4 -> 183 | E25: =E4 -> 4511.64 | F25: =F4 -> 26.1 | G25: =G4 -> 33.3 | H25: =H4 -> 29.7 | ... L25: =L4 -> 2 | M25: 0 | N25: 0 | O25: =N25*0.01 -> 0
A26: =A5 -> 2003 | B26: =B5 -> 3 | C26: =C5 -> 2003 | D26: =D5 -> 183 | E26: =E5 -> 4511.64 | F26: =F5 -> 26.1 | G26: =G5 -> 33.25 | H26: =H5 -> 29.68 | ... L26: =L5 -> 2 | M26: 0 | N26: 0 | O26: =N26*0.01 -> 0
A27: =A6 -> 2004 | B27: =B6 -> 3 | C27: =C6 -> 2004 | D27: =D6 -> 183.5 | E27: =E6 -> 4514.7 | F27: =F6 -> 25.6 | G27: =G6 -> 32.56 | H27: =H6 -> 29.08 | ... L27: =L6 -> 2 | M27: 0 | N27: 0 | O27: =N27*0.01 -> 0
A28: =A7 -> 2005 | B28: =B7 -> 3 | C28: =C7 -> 2005 | D28: =D7 -> 183 | E28: =E7 -> 4511.64 | F28: =F7 -> 25.83 | G28: =G7 -> 32.7 | H28: =H7 -> 29.26 | ... L28: =L7 -> 2 | M28: 0 | N28: 0 | O28: =N28*0.01 -> 0
A29: =A8 -> 2006 | B29: =B8 -> 3 | C29: =C8 -> 2006 | D29: =D8 -> 183 | E29: =E8 -> 4511.64 | F29: =F8 -> 26.24 | G29: =G8 -> 33.25 | H29: =H8 -> 29.74 | ... L29: =L8 -> 2 | M29: 0 | N29: 0 | O29: =N29*0.01 -> 0
A30: =A9 -> 2007 | B30: =B9 -> 3 | C30: =C9 -> 2007 | D30: =D9 -> 183 | E30: =E9 -> 4511.64 | F30: =F9 -> 25.7 | G30: =G9 -> 32.76 | H30: =H9 -> 29.23 | ... L30: =L9 -> 2 | M30: 0 | N30: 0 | O30: =N30*0.01 -> 0
A31: =A10 -> 2008 | B31: =B10 -> 3 | C31: =C10 -> 2008 | D31: =D10 -> 183.5 | E31: =E10 -> 4514.7 | F31: =F10 -> 25.54 | G31: =G10 -> 32.39 | H31: =H10 -> 28.97 | ... L31: =L10 -> 2 | M31: 0 | N31: 0 | O31: =N31*0.01 -> 0
A32: =A11 -> 2009 | B32: =B11 -> 3 | C32: =C11 -> 2009 | D32: =D11 -> 183 | E32: =E11 -> 4511.64 | F32: =F11 -> 26.11 | G32: =G11 -> 33.18 | H32: =H11 -> 29.64 | ... L32: =L11 -> 2 | M32: 0 | N32: 0 | O32: =N32*0.01 -> 0
A33: =A12 -> 2010 | B33: =B12 -> 3 | C33: =C12 -> 2010 | D33: =D12 -> 183 | E33: =E12 -> 4511.64 | F33: =F12 -> 25.73 | G33: =G12 -> 32.41 | H33: =H12 -> 29.07 | ... L33: =L12 -> 2 | M33: 0 | N33: 0 | O33: =N33*0.01 -> 0
A34: =A13 -> 2011 | B34: =B13 -> 3 | C34: =C13 -> 2011 | D34: =D13 -> 183 | E34: =E13 -> 4511.64 | F34: =F13 -> 25.04 | G34: =G13 -> 32.79 | H34: =H13 -> 28.91 | ... L34: =L13 -> 2 | M34: 0 | N34: 0 | O34: =N34*0.01 -> 0
... A43: =A22 -> 2020 | B43: =B22 -> 3 | C43: =C22 -> 2020 | D43: =D22 -> 183.5 | E43: =E22 -> 4368.14 | F43: =F22 -> 25.43 | G43: =G22 -> 33.82 | H43: =H22 -> 29.63 | ... L43: =L22 -> 2 | M43: 0 | N43: 0 | O43: =N43*0.01 -> 0

Sheet Resumen_Guajira4
A1: Hoja | B1: Station Number | C1: Año | D1: Día | E1: Irradiacion | F1: Min Temp | G1: Max Temp | H1: Temp Promedio | I1: Vapor | J1: Wind Speed | K1: Precipitacion | L1: Departamento | M1: Irrigacion | N1: Produccion | O1: Toneladas por hectaria
A2: 2000 | B2: 4 | C2: 2000 | D2: 183.5 | E2: 5116.6 | F2: 23.69 | G2: 32.77 | H2: 28.23 | I2: 38.44 | J2: 3.41 | K2: 0.45 | L2: 2 | M2: 1 | N2: {=TRANSPOSE('4_2000_2020'!B273:AQ273)} -> 6554.5233 | O2: =N2*0.01 -> 65.545233
A3: 2001 | B3: 4 | C3: 2001 | D3: 183 | E3: 5116.27 | F3: 24.02 | G3: 33.62 | H3: 28.82 | I3: 39.78 | J3: 6.69 | K3: 0.45 | L3: 2 | M3: 1 | N3: 6672.4671 | O3: =N3*0.01 -> 66.724671
A4: 2002 | B4: 4 | C4: 2002 | D4: 183 | E4: 5116.27 | F4: 24.83 | G4: 33.59 | H4: 29.21 | I4: 40.65 | J4: 15.41 | K4: 0.45 | L4: 2 | M4: 1 | N4: 8294.456 | O4: =N4*0.01 -> 82.94456
A5: 2003 | B5: 4 | C5: 2003 | D5: 183 | E5: 5116.27 | F5: 24.64 | G5: 33.75 | H5: 29.2 | I5: 40.62 | J5: 20.83 | K5: 0.45 | L5: 2 | M5: 1 | N5: 7178.1623 | O5: =N5*0.01 -> 71.781623
A6: 2004 | B6: 4 | C6: 2004 | D6: 183.5 | E6: 5116.6 | F6: 24.58 | G6: 33.01 | H6: 28.8 | I6: 39.75 | J6: 24.51 | K6: 0.45 | L6: 2 | M6: 1 | N6: 7993.3963 | O6: =N6*0.01 -> 79.933963
A7: 2005 | B7: 4 | C7: 2005 | D7: 183 | E7: 5116.27 | F7: 24.37 | G7: 32.98 | H7: 28.67 | I7: 39.48 | J7: 13.37 | K7: 0.45 | L7: 2 | M7: 1 | N7: 5770.7118 | O7: =N7*0.01 -> 57.707118
A8: 2006 | B8: 4 | C8: 2006 | D8: 183 | E8: 5116.27 | F8: 24.68 | G8: 33.42 | H8: 29.05 | I8: 40.29 | J8: 19.56 | K8: 0.45 | L8: 2 | M8: 1 | N8: 7877.1688 | O8: =N8*0.01 -> 78.771688
A9: 2007 | B9: 4 | C9: 2007 | D9: 183 | E9: 5116.27 | F9: 24.53 | G9: 33.18 | H9: 28.86 | I9: 39.82 | J9: 20.51 | K9: 0.45 | L9: 2 | M9: 1 | N9: 7553.0877 | O9: =N9*0.01 -> 75.530877
A10: 2008 | B10: 4 | C10: 2008 | D10: 183.5 | E10: 5116.6 | F10: 23.89 | G10: 33.05 | H10: 28.47 | I10: 38.96 | J10: 16.22 | K10: 0.45 | L10: 2 | M10: 1 | N10: 7322.0624 | O10: =N10*0.01 -> 73.220624
A11: 2009 | B11: 4 | C11: 2009 | D11: 183 | E11: 5116.27 | F11: 24.45 | G11: 33.97 | H11: 29.21 | I11: 40.7 | J11: 24.62 | K11: 0.45 | L11: 2 | M11: 1 | N11: 8458.1679 | O11: =N11*0.01 -> 84.581679
A12: 2010 | B12: 4 | C12: 2010 | D12: 183 | E12: 5116.27 | F12: 24.25 | G12: 33.39 | H12: 28.82 | I12: 39.78 | J12: 24.44 | K12: 0.45 | L12: 2 | M12: 1 | N12: 7434.8243 | O12: =N12*0.01 -> 74.348243
A13: 2011 | B13: 4 | C13: 2011 | D13: 183 | E13: 5116.27 | F13: 23.8 | G13: 32.68 | H13: 28.24 | I13: 38.44 | J13: 24.12 | K13: 0.45 | L13: 2 | M13: 1 | N13: 8466.7123 | O13: =N13*0.01 -> 84.667123
A14: 2012 | B14: 4 | C14: 2012 | D14: 183.5 | E14: 5116.6 | F14: 24.46 | G14: 33.49 | H14: 28.98 | I14: 40.13 | J14: 24.53 | K14: 0.45 | L14: 2 | M14: 1 | N14: 8029.3251 | O14: =N14*0.01 -> 80.293251
... A22: 2020 | B22: 4 | C22: 2020 | D22: 183.5 | E22: 5130.26 | F22: 25.48 | G22: 34.07 | H22: 29.78 | I22: 42.02 | J22: 24.87 | K22: 1.05 | L22: 2 | M22: 1 | N22: 7222.3826 | O22: =N22*0.01 -> 72.223826
A23: =A2 -> 2000 | B23: =B2 -> 4 | C23: =C2 -> 2000 | D23: =D2 -> 183.5 | E23: =E2 -> 5116.6 | F23: =F2 -> 23.69 | G23: =G2 -> 32.77 | H23: =H2 -> 28.23 | ... L23: =L2 -> 2 | M23: 0 | N23: 0.024250421 | O23: =N23*0.01 -> 0.00024250421
A24: =A3 -> 2001 | B24: =B3 -> 4 | C24: =C3 -> 2001 | D24: =D3 -> 183 | E24: =E3 -> 5116.27 | F24: =F3 -> 24.02 | G24: =G3 -> 33.62 | H24: =H3 -> 28.82 | ... L24: =L3 -> 2 | M24: 0 | N24: 0.019028387 | O24: =N24*0.01 -> 0.00019028387
A25: =A4 -> 2002 | B25: =B4 -> 4 | C25: =C4 -> 2002 | D25: =D4 -> 183 | E25: =E4 -> 5116.27 | F25: =F4 -> 24.83 | G25: =G4 -> 33.59 | H25: =H4 -> 29.21 | ... L25: =L4 -> 2 | M25: 0 | N25: 0.020688743 | O25: =N25*0.01 -> 0.00020688743
A26: =A5 -> 2003 | B26: =B5 -> 4 | C26: =C5 -> 2003 | D26: =D5 -> 183 | E26: =E5 -> 5116.27 | F26: =F5 -> 24.64 | G26: =G5 -> 33.75 | H26: =H5 -> 29.2 | ... L26: =L5 -> 2 | M26: 0 | N26: 0.016273281 | O26: =N26*0.01 -> 0.00016273281
A27: =A6 -> 2004 | B27: =B6 -> 4 | C27: =C6 -> 2004 | D27: =D6 -> 183.5 | E27: =E6 -> 5116.6 | F27: =F6 -> 24.58 | G27: =G6 -> 33.01 | H27: =H6 -> 28.8 | ... L27: =L6 -> 2 | M27: 0 | N27: 0.016914088 | O27: =N27*0.01 -> 0.00016914088
A28: =A7 -> 2005 | B28: =B7 -> 4 | C28: =C7 -> 2005 | D28: =D7 -> 183 | E28: =E7 -> 5116.27 | F28: =F7 -> 24.37 | G28: =G7 -> 32.98 | H28: =H7 -> 28.67 | ... L28: =L7 -> 2 | M28: 0 | N28: 0.013690665 | O28: =N28*0.01 -> 0.00013690665
A29: =A8 -> 2006 | B29: =B8 -> 4 | C29: =C8 -> 2006 | D29: =D8 -> 183 | E29: =E8 -> 5116.27 | F29: =F8 -> 24.68 | G29: =G8 -> 33.42 | H29: =H8 -> 29.05 | ... L29: =L8 -> 2 | M29: 0 | N29: 0.019057549 | O29: =N29*0.01 -> 0.00019057549
A30: =A9 -> 2007 | B30: =B9 -> 4 | C30: =C9 -> 2007 | D30: =D9 -> 183 | E30: =E9 -> 5116.27 | F30: =F9 -> 24.53 | G30: =G9 -> 33.18 | H30: =H9 -> 28.86 | ... L30: =L9 -> 2 | M30: 0 | N30: 0.014992944 | O30: =N30*0.01 -> 0.00014992944
A31: =A10 -> 2008 | B31: =B10 -> 4 | C31: =C10 -> 2008 | D31: =D10 -> 183.5 | E31: =E10 -> 5116.6 | F31: =F10 -> 23.89 | G31: =G10 -> 33.05 | H31: =H10 -> 28.47 | ... L31: =L10 -> 2 | M31: 0 | N31: 0.017488541 | O31: =N31*0.01 -> 0.00017488541
A32: =A11 -> 2009 | B32: =B11 -> 4 | C32: =C11 -> 2009 | D32: =D11 -> 183 | E32: =E11 -> 5116.27 | F32: =F11 -> 24.45 | G32: =G11 -> 33.97 | H32: =H11 -> 29.21 | ... L32: =L11 -> 2 | M32: 0 | N32: 0.028074095 | O32: =N32*0.01 -> 0.00028074095
A33: =A12 -> 2010 | B33: =B12 -> 4 | C33: =C12 -> 2010 | D33: =D12 -> 183 | E33: =E12 -> 5116.27 | F33: =F12 -> 24.25 | G33: =G12 -> 33.39 | H33: =H12 -> 28.82 | ... L33: =L12 -> 2 | M33: 0 | N33: 0.011818651 | O33: =N33*0.01 -> 0.00011818651
A34: =A13 -> 2011 | B34: =B13 -> 4 | C34: =C13 -> 2011 | D34: =D13 -> 183 | E34: =E13 -> 5116.27 | F34: =F13 -> 23.8 | G34: =G13 -> 32.68 | H34: =H13 -> 28.24 | ... L34: =L13 -> 2 | M34: 0 | N34: 0.024868734 | O34: =N34*0.01 -> 0.00024868734
... A43: =A22 -> 2020 | B43: =B22 -> 4 | C43: =C22 -> 2020 | D43: =D22 -> 183.5 | E43: =E22 -> 5130.26 | F43: =F22 -> 25.48 | G43: =G22 -> 34.07 | H43: =H22 -> 29.78 | ... L43: =L22 -> 2 | M43: 0 | N43: 0 | O43: =N43*0.01 -> 0

Sheet Resumen_Antioquia5
A1: Hoja | B1: Station Number | C1: Año | D1: Día | E1: Irradiacion | F1: Min Temp | G1: Max Temp | H1: Temp Promedio | I1: Vapor | J1: Wind Speed | K1: Precipitacion | L1: Departamento | M1: Irrigacion | N1: Produccion | O1: Toneladas por hectaria
A2: 2000 | B2: 5 | C2: 2000 | D2: 183.5 | E2: 4419.07 | F2: 17.94 | G2: 27.13 | H2: 22.54 | I2: 27.37 | J2: 1.37 | K2: 3.13 | L2: 3 | M2: 1 | N2: {=TRANSPOSE('5_2000_2020'!B273:AO273)} -> 9093.0683 | O2: =N2*0.01 -> 90.930683
A3: 2001 | B3: 5 | C3: 2001 | D3: 183 | E3: 4418.41 | F3: 18.24 | G3: 28.08 | H3: 23.16 | I3: 28.43 | J3: 1.34 | K3: 3.13 | L3: 3 | M3: 1 | N3: 8650.7744 | O3: =N3*0.01 -> 86.507744
A4: 2002 | B4: 5 | C4: 2002 | D4: 183 | E4: 4418.41 | F4: 18.55 | G4: 28.42 | H4: 23.49 | I4: 29.01 | J4: 1.32 | K4: 3.13 | L4: 3 | M4: 1 | N4: 8475.7823 | O4: =N4*0.01 -> 84.757823
A5: 2003 | B5: 5 | C5: 2003 | D5: 183 | E5: 4418.41 | F5: 18.52 | G5: 28.09 | H5: 23.3 | I5: 28.68 | J5: 1.3 | K5: 3.13 | L5: 3 | M5: 1 | N5: 8481.0286 | O5: =N5*0.01 -> 84.810286
A6: 2004 | B6: 5 | C6: 2004 | D6: 183.5 | E6: 4419.07 | F6: 18.35 | G6: 28.11 | H6: 23.23 | I6: 28.56 | J6: 1.34 | K6: 3.13 | L6: 3 | M6: 1 | N6: 8737.7168 | O6: =N6*0.01 -> 87.377168
A7: 2005 | B7: 5 | C7: 2005 | D7: 183 | E7: 4418.41 | F7: 18.52 | G7: 28.49 | H7: 23.51 | I7: 29.04 | J7: 1.33 | K7: 3.13 | L7: 3 | M7: 1 | N7: 8508.1928 | O7: =N7*0.01 -> 85.081928
A8: 2006 | B8: 5 | C8: 2006 | D8: 183 | E8: 4418.41 | F8: 18.48 | G8: 28.24 | H8: 23.36 | I8: 28.78 | J8: 1.27 | K8: 3.13 | L8: 3 | M8: 1 | N8: 8875.3524 | O8: =N8*0.01 -> 88.753524
A9: 2007 | B9: 5 | C9: 2007 | D9: 183 | E9: 4418.41 | F9: 18.3 | G9: 28 | H9: 23.15 | I9: 28.43 | J9: 1.26 | K9: 3.13 | L9: 3 | M9: 1 | N9: 8727.1923 | O9: =N9*0.01 -> 87.271923
A10: 2008 | B10: 5 | C10: 2008 | D10: 183.5 | E10: 4419.07 | F10: 17.91 | G10: 27.39 | H10: 22.65 | I10: 27.56 | J10: 1.15 | K10: 3.13 | L10: 3 | M10: 1 | N10: 8791.2755 | O10: =N10*0.01 -> 87.912755
A11: 2009 | B11: 5 | C11: 2009 | D11: 183 | E11: 4418.41 | F11: 18.6 | G11: 28.28 | H11: 23.44 | I11: 28.92 | J11: 1.3 | K11: 3.13 | L11: 3 | M11: 1 | N11: 8727.001 | O11: =N11*0.01 -> 87.27001
A12: 2010 | B12: 5 | C12: 2010 | D12: 183 | E12: 4418.41 | F12: 18.75 | G12: 28.01 | H12: 23.38 | I12: 28.86 | J12: 1.26 | K12: 3.13 | L12: 3 | M12: 1 | N12: 8004.8641 | O12: =N12*0.01 -> 80.048641
A13: 2011 | B13: 5 | C13: 2011 | D13: 183 | E13: 4418.41 | F13: 18.32 | G13: 26.99 | H13: 22.65 | I13: 27.57 | J13: 1.26 | K13: 3.13 | L13: 3 | M13: 1 | N13: 8794.8575 | O13: =N13*0.01 -> 87.948575
A14: 2012 | B14: 5 | C14: 2012 | D14: 183.5 | E14: 4419.07 | F14: 18.42 | G14: 27.96 | H14: 23.19 | I14: 28.48 | J14: 1.34 | K14: 3.13 | L14: 3 | M14: 1 | N14: 8639.9657 | O14: =N14*0.01 -> 86.399657
... A21: 2019 | B21: 5 | C21: 2019 | D21: 183 | E21: 4412.94 | F21: 18.98 | G21: 28.73 | H21: 23.86 | I21: 29.65 | J21: 1.3 | K21: 3.12 | L21: 3 | M21: 1 | N21: 8511.6721 | O21: =N21*0.01 -> 85.116721
A22: =A2 -> 2000 | B22: =B2 -> 5 | C22: =C2 -> 2000 | D22: =D2 -> 183.5 | E22: =E2 -> 4419.07 | F22: =F2 -> 17.94 | G22: =G2 -> 27.13 | H22: =H2 -> 22.54 | ... L22: =L2 -> 3 | M22: 0 | N22: 1.9967441 | O22: =N22*0.01 -> 0.019967441
A23: =A3 -> 2001 | B23: =B3 -> 5 | C23: =C3 -> 2001 | D23: =D3 -> 183 | E23: =E3 -> 4418.41 | F23: =F3 -> 18.24 | G23: =G3 -> 28.08 | H23: =H3 -> 23.16 | ... L23: =L3 -> 3 | M23: 0 | N23: 1.7799403 | O23: =N23*0.01 -> 0.017799403
A24: =A4 -> 2002 | B24: =B4 -> 5 | C24: =C4 -> 2002 | D24: =D4 -> 183 | E24: =E4 -> 4418.41 | F24: =F4 -> 18.55 | G24: =G4 -> 28.42 | H24: =H4 -> 23.49 | ... L24: =L4 -> 3 | M24: 0 | N24: 1.5521245 | O24: =N24*0.01 -> 0.015521245
A25: =A5 -> 2003 | B25: =B5 -> 5 | C25: =C5 -> 2003 | D25: =D5 -> 183 | E25: =E5 -> 4418.41 | F25: =F5 -> 18.52 | G25: =G5 -> 28.09 | H25: =H5 -> 23.3 | ... L25: =L5 -> 3 | M25: 0 | N25: 1.5948571 | O25: =N25*0.01 -> 0.015948571
A26: =A6 -> 2004 | B26: =B6 -> 5 | C26: =C6 -> 2004 | D26: =D6 -> 183.5 | E26: =E6 -> 4419.07 | F26: =F6 -> 18.35 | G26: =G6 -> 28.11 | H26: =H6 -> 23.23 | ... L26: =L6 -> 3 | M26: 0 | N26: 1.4193072 | O26: =N26*0.01 -> 0.014193072
A27: =A7 -> 2005 | B27: =B7 -> 5 | C27: =C7 -> 2005 | D27: =D7 -> 183 | E27: =E7 -> 4418.41 | F27: =F7 -> 18.52 | G27: =G7 -> 28.49 | H27: =H7 -> 23.51 | ... L27: =L7 -> 3 | M27: 0 | N27: 1.3812841 | O27: =N27*0.01 -> 0.013812841
A28: =A8 -> 2006 | B28: =B8 -> 5 | C28: =C8 -> 2006 | D28: =D8 -> 183 | E28: =E8 -> 4418.41 | F28: =F8 -> 18.48 | G28: =G8 -> 28.24 | H28: =H8 -> 23.36 | ... L28: =L8 -> 3 | M28: 0 | N28: 1.7457123 | O28: =N28*0.01 -> 0.017457123
A29: =A9 -> 2007 | B29: =B9 -> 5 | C29: =C9 -> 2007 | D29: =D9 -> 183 | E29: =E9 -> 4418.41 | F29: =F9 -> 18.3 | G29: =G9 -> 28 | H29: =H9 -> 23.15 | ... L29: =L9 -> 3 | M29: 0 | N29: 1.6353498 | O29: =N29*0.01 -> 0.016353498
A30: =A10 -> 2008 | B30: =B10 -> 5 | C30: =C10 -> 2008 | D30: =D10 -> 183.5 | E30: =E10 -> 4419.07 | F30: =F10 -> 17.91 | G30: =G10 -> 27.39 | H30: =H10 -> 22.65 | ... L30: =L10 -> 3 | M30: 0 | N30: 1.8619787 | O30: =N30*0.01 -> 0.018619787
A31: =A11 -> 2009 | B31: =B11 -> 5 | C31: =C11 -> 2009 | D31: =D11 -> 183 | E31: =E11 -> 4418.41 | F31: =F11 -> 18.6 | G31: =G11 -> 28.28 | H31: =H11 -> 23.44 | ... L31: =L11 -> 3 | M31: 0 | N31: 1.8475576 | O31: =N31*0.01 -> 0.018475576
A32: =A12 -> 2010 | B32: =B12 -> 5 | C32: =C12 -> 2010 | D32: =D12 -> 183 | E32: =E12 -> 4418.41 | F32: =F12 -> 18.75 | G32: =G12 -> 28.01 | H32: =H12 -> 23.38 | ... L32: =L12 -> 3 | M32: 0 | N32: 1.0429005 | O32: =N32*0.01 -> 0.010429005
A33: =A13 -> 2011 | B33: =B13 -> 5 | C33: =C13 -> 2011 | D33: =D13 -> 183 | E33: =E13 -> 4418.41 | F33: =F13 -> 18.32 | G33: =G13 -> 26.99 | H33: =H13 -> 22.65 | ... L33: =L13 -> 3 | M33: 0 | N33: 1.9999839 | O33: =N33*0.01 -> 0.019999839
... A41: =A21 -> 2019 | B41: =B21 -> 5 | C41: =C21 -> 2019 | D41: =D21 -> 183 | E41: =E21 -> 4412.94 | F41: =F21 -> 18.98 | G41: =G21 -> 28.73 | H41: =H21 -> 23.86 | ... L41: =L21 -> 3 | M41: 0 | N41: 0 | O41: =N41*0.01 -> 0

Sheet Resumen_Antioquia6
A1: Hoja | B1: Station Number | C1: Año | D1: Día | E1: Irradiacion | F1: Min Temp | G1: Max Temp | H1: Temp Promedio | I1: Vapor | J1: Wind Speed | K1: Precipitacion | L1: Departamento | M1: Irrigacion | N1: Produccion | O1: Toneladas por hectaria
A2: 2000 | B2: 6 | C2: 2000 | D2: 183.5 | E2: 4561.91 | F2: 13.52 | G2: 22.35 | H2: 17.93 | I2: 20.58 | J2: 1.27 | K2: 1.1 | L2: 3 | M2: 1 | N2: {=TRANSPOSE('6_2000_2020'!B273:AQ273)} -> 11113.78 | O2: =N2*0.01 -> 111.1378
A3: 2001 | B3: 6 | C3: 2001 | D3: 183 | E3: 4562.68 | F3: 12.64 | G3: 22.8 | H3: 17.72 | I3: 20.31 | J3: 1.3 | K3: 1.1 | L3: 3 | M3: 1 | N3: 11494.314 | O3: =N3*0.01 -> 114.94314
A4: 2002 | B4: 6 | C4: 2002 | D4: 183 | E4: 4562.68 | F4: 12.11 | G4: 23.05 | H4: 17.58 | I4: 20.13 | J4: 1.33 | K4: 1.1 | L4: 3 | M4: 1 | N4: 11143.07 | O4: =N4*0.01 -> 111.4307
A5: 2003 | B5: 6 | C5: 2003 | D5: 183 | E5: 4562.68 | F5: 12.17 | G5: 22.91 | H5: 17.54 | I5: 20.08 | J5: 1.27 | K5: 1.1 | L5: 3 | M5: 1 | N5: 11213.848 | O5: =N5*0.01 -> 112.13848
A6: 2004 | B6: 6 | C6: 2004 | D6: 183.5 | E6: 4561.91 | F6: 12.26 | G6: 22.91 | H6: 17.58 | I6: 20.14 | J6: 1.25 | K6: 1.1 | L6: 3 | M6: 1 | N6: 11311.709 | O6: =N6*0.01 -> 113.11709
A7: 2005 | B7: 6 | C7: 2005 | D7: 183 | E7: 4259.19 | F7: 12.29 | G7: 23.07 | H7: 17.68 | I7: 20.26 | J7: 1.27 | K7: 6.01 | L7: 3 | M7: 1 | N7: 11338.747 | O7: =N7*0.01 -> 113.38747
A8: 2006 | B8: 6 | C8: 2006 | D8: 183 | E8: 4359.24 | F8: 12.38 | G8: 23.09 | H8: 17.73 | I8: 20.33 | J8: 1.24 | K8: 5.27 | L8: 3 | M8: 1 | N8: 11441.727 | O8: =N8*0.01 -> 114.41727
A9: 2007 | B9: 6 | C9: 2007 | D9: 183 | E9: 4562.68 | F9: 11.95 | G9: 22.82 | H9: 17.38 | I9: 19.88 | J9: 1.2 | K9: 0 | L9: 3 | M9: 1 | N9: 10987.5 | O9: =N9*0.01 -> 109.875
A10: 2008 | B10: 6 | C10: 2008 | D10: 183.5 | E10: 4561.91 | F10: 11.47 | G10: 22.78 | H10: 17.12 | I10: 19.54 | J10: 1.17 | K10: 0 | L10: 3 | M10: 1 | N10: 10845.058 | O10: =N10*0.01 -> 108.45058
A11: 2009 | B11: 6 | C11: 2009 | D11: 183 | E11: 4562.68 | F11: 11.83 | G11: 22.67 | H11: 17.25 | I11: 19.71 | J11: 1.33 | K11: 0 | L11: 3 | M11: 1 | N11: 10985.533 | O11: =N11*0.01 -> 109.85533
A12: 2010 | B12: 6 | C12: 2010 | D12: 183 | E12: 4562.68 | F12: 12.67 | G12: 22.66 | H12: 17.66 | I12: 20.24 | J12: 1.15 | K12: 0 | L12: 3 | M12: 1 | N12: 11082.724 | O12: =N12*0.01 -> 110.82724
A13: 2011 | B13: 6 | C13: 2011 | D13: 183 | E13: 4562.68 | F13: 12.3 | G13: 22.32 | H13: 17.31 | I13: 19.78 | J13: 1.25 | K13: 1.12 | L13: 3 | M13: 1 | N13: 10883.335 | O13: =N13*0.01 -> 108.83335
A14: 2012 | B14: 6 | C14: 2012 | D14: 183.5 | E14: 4569.54 | F14: 12.3 | G14: 22.77 | H14: 17.54 | I14: 20.06 | J14: 1.25 | K14: 1.1 | L14: 3 | M14: 1 | N14: 11208.685 | O14: =N14*0.01 -> 112.08685
... A22: 2020 | B22: 6 | C22: 2020 | D22: 183.5 | E22: 4561.91 | F22: 12.3 | G22: 22.8 | H22: 17.55 | I22: 20.07 | J22: 1.25 | K22: 1.1 | L22: 3 | M22: 1 | N22: 11229.805 | O22: =N22*0.01 -> 112.29805
A23: =A2 -> 2000 | B23: =B2 -> 6 | C23: =C2 -> 2000 | D23: =D2 -> 183.5 | E23: =E2 -> 4561.91 | F23: =F2 -> 13.52 | G23: =G2 -> 22.35 | H23: =H2 -> 17.93 | ... L23: =L2 -> 3 | M23: 0 | N23: 0.0046806242 | O23: =N23*0.01 -> 4.6806242e-05
A24: =A3 -> 2001 | B24: =B3 -> 6 | C24: =C3 -> 2001 | D24: =D3 -> 183 | E24: =E3 -> 4562.68 | F24: =F3 -> 12.64 | G24: =G3 -> 22.8 | H24: =H3 -> 17.72 | ... L24: =L3 -> 3 | M24: 0 | N24: 0.0061356256 | O24: =N24*0.01 -> 6.1356256e-05
A25: =A4 -> 2002 | B25: =B4 -> 6 | C25: =C4 -> 2002 | D25: =D4 -> 183 | E25: =E4 -> 4562.68 | F25: =F4 -> 12.11 | G25: =G4 -> 23.05 | H25: =H4 -> 17.58 | ... L25: =L4 -> 3 | M25: 0 | N25: 0.0068437668 | O25: =N25*0.01 -> 6.8437668e-05
A26: =A5 -> 2003 | B26: =B5 -> 6 | C26: =C5 -> 2003 | D26: =D5 -> 183 | E26: =E5 -> 4562.68 | F26: =F5 -> 12.17 | G26: =G5 -> 22.91 | H26: =H5 -> 17.54 | ... L26: =L5 -> 3 | M26: 0 | N26: 0.0082246667 | O26: =N26*0.01 -> 8.2246667e-05
A27: =A6 -> 2004 | B27: =B6 -> 6 | C27: =C6 -> 2004 | D27: =D6 -> 183.5 | E27: =E6 -> 4561.91 | F27: =F6 -> 12.26 | G27: =G6 -> 22.91 | H27: =H6 -> 17.58 | ... L27: =L6 -> 3 | M27: 0 | N27: 0.006908816 | O27: =N27*0.01 -> 6.908816e-05
A28: =A7 -> 2005 | B28: =B7 -> 6 | C28: =C7 -> 2005 | D28: =D7 -> 183 | E28: =E7 -> 4259.19 | F28: =F7 -> 12.29 | G28: =G7 -> 23.07 | H28: =H7 -> 17.68 | ... L28: =L7 -> 3 | M28: 0 | N28: 5.5872508 | O28: =N28*0.01 -> 0.055872508
A29: =A8 -> 2006 | B29: =B8 -> 6 | C29: =C8 -> 2006 | D29: =D8 -> 183 | E29: =E8 -> 4359.24 | F29: =F8 -> 12.38 | G29: =G8 -> 23.09 | H29: =H8 -> 17.73 | ... L29: =L8 -> 3 | M29: 0 | N29: 0 | O29: =N29*0.01 -> 0
A30: =A9 -> 2007 | B30: =B9 -> 6 | C30: =C9 -> 2007 | D30: =D9 -> 183 | E30: =E9 -> 4562.68 | F30: =F9 -> 11.95 | G30: =G9 -> 22.82 | H30: =H9 -> 17.38 | ... L30: =L9 -> 3 | M30: 0 | N30: 0 | O30: =N30*0.01 -> 0
A31: =A10 -> 2008 | B31: =B10 -> 6 | C31: =C10 -> 2008 | D31: =D10 -> 183.5 | E31: =E10 -> 4561.91 | F31: =F10 -> 11.47 | G31: =G10 -> 22.78 | H31: =H10 -> 17.12 | ... L31: =L10 -> 3 | M31: 0 | N31: 0 | O31: =N31*0.01 -> 0
A32: =A11 -> 2009 | B32: =B11 -> 6 | C32: =C11 -> 2009 | D32: =D11 -> 183 | E32: =E11 -> 4562.68 | F32: =F11 -> 11.83 | G32: =G11 -> 22.67 | H32: =H11 -> 17.25 | ... L32: =L11 -> 3 | M32: 0 | N32: 0 | O32: =N32*0.01 -> 0
